Workbook
Name Slicer_Customer_ID: #N/A
Name Slicer_Dessert_ID: #N/A
Name Slicer_Discount_Eligible: #N/A
Name Slicer_Restaurant_ID: #N/A

Sheet Restaurants
A1: Restaurant_ID | B1: Restaurant_Name | C1: City | D1: Owner | E1: Rating
A2: R001 | B2: Restaurant_1 | C2: Bangalore | D2: Owner_1 | E2: 4.2
A3: R002 | B3: Restaurant_2 | C3: Pune | D3: Owner_2 | E3: 4.8
A4: R003 | B4: Restaurant_3 | C4: Hyderabad | D4: Owner_3 | E4: 4.9
A5: R004 | B5: Restaurant_4 | C5: Hyderabad | D5: Owner_4 | E5: 3.8
A6: R005 | B6: Restaurant_5 | C6: Mumbai | D6: Owner_5 | E6: 3.7
A7: R006 | B7: Restaurant_6 | C7: Hyderabad | D7: Owner_6 | E7: 3.6
A8: R007 | B8: Restaurant_7 | C8: Mumbai | D8: Owner_7 | E8: 4.3
A9: R008 | B9: Restaurant_8 | C9: Mumbai | D9: Owner_8 | E9: 3.6
A10: R009 | B10: Restaurant_9 | C10: Kolkata | D10: Owner_9 | E10: 4
A11: R010 | B11: Restaurant_10 | C11: Hyderabad | D11: Owner_10 | E11: 4.6
A12: R011 | B12: Restaurant_11 | C12: Bangalore | D12: Owner_11 | E12: 3.7
A13: R012 | B13: Restaurant_12 | C13: Delhi | D13: Owner_12 | E13: 5
... A101: R100 | B101: Restaurant_100 | C101: Bangalore | D101: Owner_100 | E101: 4.6

Sheet Customers
A1: Customer_ID | B1: Name | C1: Phone | D1: City | E1: Total_Orders
A2: C001 | B2: Customer_1 | C2: 7622636195 | D2: Pune | E2: 488
A3: C002 | B3: Customer_2 | C3: 7677852174 | D3: Mumbai | E3: 1700
A4: C003 | B4: Customer_3 | C4: 9483150364 | D4: Pune | E4: 760
A5: C004 | B5: Customer_4 | C5: 8864954923 | D5: Kolkata | E5: 889
A6: C005 | B6: Customer_5 | C6: 9441942491 | D6: Kolkata | E6: 616
A7: C006 | B7: Customer_6 | C7: 8600254397 | D7: Mumbai | E7: 1734
A8: C007 | B8: Customer_7 | C8: 9693827318 | D8: Jaipur | E8: 1527
A9: C008 | B9: Customer_8 | C9: 7432720750 | D9: Jaipur | E9: 1532
A10: C009 | B10: Customer_9 | C10: 8921925429 | D10: Kolkata | E10: 1615
A11: C010 | B11: Customer_10 | C11: 8323773962 | D11: Jaipur | E11: 443
A12: C011 | B12: Customer_11 | C12: 8421613577 | D12: Delhi | E12: 670
A13: C012 | B13: Customer_12 | C13: 9906882385 | D13: Bangalore | E13: 375
... A101: C100 | B101: Customer_100 | C101: 7889849431 | D101: Kolkata | E101: 1785

Sheet Desserts
A1: Dessert_ID | B1: Dessert_Name | C1: Original_Price | D1: Cost_Price
A2: D001 | B2: Muffin_1 | C2: 134 | D2: 64
A3: D002 | B3: Muffin_2 | C3: 221 | D3: 68
A4: D003 | B4: GulabJamun_3 | C4: 168 | D4: 84
A5: D004 | B5: IceCream_4 | C5: 146 | D5: 43
A6: D005 | B6: Brownie_5 | C6: 204 | D6: 68
A7: D006 | B7: Muffin_6 | C7: 227 | D7: 85
A8: D007 | B8: Brownie_7 | C8: 238 | D8: 67
A9: D008 | B9: Pudding_8 | C9: 232 | D9: 74
A10: D009 | B10: Muffin_9 | C10: 205 | D10: 84
A11: D010 | B11: Muffin_10 | C11: 155 | D11: 62
A12: D011 | B12: IceCream_11 | C12: 184 | D12: 57
A13: D012 | B13: Pudding_12 | C13: 214 | D13: 73
... A51: D050 | B51: IceCream_50 | C51: 101 | D51: 81

Sheet Orders
A1: Order_ID | B1: Date | C1: Customer_ID | D1: Restaurant_ID | E1: Dessert_ID | F1: Quantity | G1: Price_Per_Item | H1: Discount_Eligible | I1: Discounted_Price | J1: Profit
A2: O0001 | B2: 2025-11-26 | C2: C016 | D2: R003 | E2: D044 | F2: 3 | G2: 173 | H2: =IF(VLOOKUP(C2,Customers!A:E,5,FALSE)>=1000,"YES","NO") -> YES | I2: =IF(H2="YES",G2*0.5,G2) -> 86.5 | J2: =(I2 - VLOOKUP(E2,Desserts!A:D,4,FALSE)) * F2 -> 49.5
A3: O0002 | B3: 2025-07-06 | C3: C069 | D3: R097 | E3: D001 | F3: 4 | G3: 135 | H3: =IF(VLOOKUP(C3,Customers!A:E,5,FALSE)>=1000,"YES","NO") -> YES | I3: =IF(H3="YES",G3*0.5,G3) -> 67.5 | J3: =(I3 - VLOOKUP(E3,Desserts!A:D,4,FALSE)) * F3 -> 14
A4: O0003 | B4: 2025-07-08 | C4: C079 | D4: R060 | E4: D015 | F4: 1 | G4: 142 | H4: =IF(VLOOKUP(C4,Customers!A:E,5,FALSE)>=1000,"YES","NO") -> NO | I4: =IF(H4="YES",G4*0.5,G4) -> 142 | J4: =(I4 - VLOOKUP(E4,Desserts!A:D,4,FALSE)) * F4 -> 63
A5: O0004 | B5: 2025-06-29 | C5: C097 | D5: R074 | E5: D042 | F5: 4 | G5: 188 | H5: =IF(VLOOKUP(C5,Customers!A:E,5,FALSE)>=1000,"YES","NO") -> NO | I5: =IF(H5="YES",G5*0.5,G5) -> 188 | J5: =(I5 - VLOOKUP(E5,Desserts!A:D,4,FALSE)) * F5 -> 396
A6: O0005 | B6: 2025-04-07 | C6: C021 | D6: R023 | E6: D031 | F6: 4 | G6: 161 | H6: =IF(VLOOKUP(C6,Customers!A:E,5,FALSE)>=1000,"YES","NO") -> NO | I6: =IF(H6="YES",G6*0.5,G6) -> 161 | J6: =(I6 - VLOOKUP(E6,Desserts!A:D,4,FALSE)) * F6 -> 288
A7: O0006 | B7: 2025-09-01 | C7: C062 | D7: R020 | E7: D034 | F7: 2 | G7: 158 | H7: =IF(VLOOKUP(C7,Customers!A:E,5,FALSE)>=1000,"YES","NO") -> YES | I7: =IF(H7="YES",G7*0.5,G7) -> 79 | J7: =(I7 - VLOOKUP(E7,Desserts!A:D,4,FALSE)) * F7 -> 14
A8: O0007 | B8: 2025-03-17 | C8: C074 | D8: R072 | E8: D009 | F8: 5 | G8: 160 | H8: =IF(VLOOKUP(C8,Customers!A:E,5,FALSE)>=1000,"YES","NO") -> NO | I8: =IF(H8="YES",G8*0.5,G8) -> 160 | J8: =(I8 - VLOOKUP(E8,Desserts!A:D,4,FALSE)) * F8 -> 380
A9: O0008 | B9: 2025-02-11 | C9: C044 | D9: R095 | E9: D023 | F9: 4 | G9: 179 | H9: =IF(VLOOKUP(C9,Customers!A:E,5,FALSE)>=1000,"YES","NO") -> NO | I9: =IF(H9="YES",G9*0.5,G9) -> 179 | J9: =(I9 - VLOOKUP(E9,Desserts!A:D,4,FALSE)) * F9 -> 552
A10: O0009 | B10: 2025-03-07 | C10: C100 | D10: R054 | E10: D010 | F10: 4 | G10: 139 | H10: =IF(VLOOKUP(C10,Customers!A:E,5,FALSE)>=1000,"YES","NO") -> YES | I10: =IF(H10="YES",G10*0.5,G10) -> 69.5 | J10: =(I10 - VLOOKUP(E10,Desserts!A:D,4,FALSE)) * F10 -> 30
A11: O0010 | B11: 2025-10-21 | C11: C013 | D11: R049 | E11: D030 | F11: 5 | G11: 248 | H11: =IF(VLOOKUP(C11,Customers!A:E,5,FALSE)>=1000,"YES","NO") -> YES | I11: =IF(H11="YES",G11*0.5,G11) -> 124 | J11: =(I11 - VLOOKUP(E11,Desserts!A:D,4,FALSE)) * F11 -> 310
A12: O0011 | B12: 2025-09-27 | C12: C051 | D12: R049 | E12: D049 | F12: 3 | G12: 178 | H12: =IF(VLOOKUP(C12,Customers!A:E,5,FALSE)>=1000,"YES","NO") -> YES | I12: =IF(H12="YES",G12*0.5,G12) -> 89 | J12: =(I12 - VLOOKUP(E12,Desserts!A:D,4,FALSE)) * F12 -> 144
A13: O0012 | B13: 2025-09-27 | C13: C034 | D13: R073 | E13: D004 | F13: 2 | G13: 240 | H13: =IF(VLOOKUP(C13,Customers!A:E,5,FALSE)>=1000,"YES","NO") -> NO | I13: =IF(H13="YES",G13*0.5,G13) -> 240 | J13: =(I13 - VLOOKUP(E13,Desserts!A:D,4,FALSE)) * F13 -> 394
... A501: O0500 | B501: 2025-11-10 | C501: C035 | D501: R096 | E501: D003 | F501: 2 | G501: 159 | H501: =IF(VLOOKUP(C501,Customers!A:E,5,FALSE)>=1000,"YES","NO") -> YES | I501: =IF(H501="YES",G501*0.5,G501) -> 79.5 | J501: =(I501 - VLOOKUP(E501,Desserts!A:D,4,FALSE)) * F501 -> -9

Sheet Dashboard
A1: Use Pivot Tables and Charts Here
B6: Sum of Profit | C6: Sum of Quantity | D6: Count of Order_ID
A7: C001 | B7: 905 | C7: 6 | D7: 3
A8: C002 | B8: 164.5 | C8: 7 | D8: 3
A9: C003 | B9: 2113 | C9: 19 | D9: 7
A10: C004 | B10: 1498 | C10: 17 | D10: 5
A11: C005 | B11: 1962 | C11: 12 | D11: 4
A12: C006 | B12: 323.5 | C12: 11 | D12: 3
A13: C007 | B13: 760.5 | C13: 21 | D13: 7
A14: C008 | B14: 270 | C14: 22 | D14: 8
A15: C009 | B15: -32 | C15: 5 | D15: 2
A16: C010 | B16: 1304 | C16: 17 | D16: 7
A17: C011 | B17: 1181 | C17: 10 | D17: 4
A18: C012 | B18: 1571 | C18: 18 | D18: 5
... A844: Grand Total | B844: 99689.5 | C844: 1480 | D844: 500

Sheet TotalProfit_Restaurent
A1: Order_ID | B1: Date | C1: Customer_ID | D1: Restaurant_ID | E1: Dessert_ID | F1: Quantity | G1: Price_Per_Item | H1: Discount_Eligible | I1: Discounted_Price | J1: Profit
A2: O0001 | B2: 2025-11-26 | C2: C016 | D2: R003 | E2: D044 | F2: 3 | G2: 173 | H2: =IF(VLOOKUP(C2,Customers!A:E,5,FALSE)>=1000,"YES","NO") -> YES | I2: =IF(H2="YES",G2*0.5,G2) -> 86.5 | J2: =(I2 - VLOOKUP(E2,Desserts!A:D,4,FALSE)) * F2 -> 49.5 | O2: Total Profit by Restaurant
A3: O0002 | B3: 2025-07-06 | C3: C069 | D3: R097 | E3: D001 | F3: 4 | G3: 135 | H3: =IF(VLOOKUP(C3,Customers!A:E,5,FALSE)>=1000,"YES","NO") -> YES | I3: =IF(H3="YES",G3*0.5,G3) -> 67.5 | J3: =(I3 - VLOOKUP(E3,Desserts!A:D,4,FALSE)) * F3 -> 14
A4: O0003 | B4: 2025-07-08 | C4: C079 | D4: R060 | E4: D015 | F4: 1 | G4: 142 | H4: =IF(VLOOKUP(C4,Customers!A:E,5,FALSE)>=1000,"YES","NO") -> NO | I4: =IF(H4="YES",G4*0.5,G4) -> 142 | J4: =(I4 - VLOOKUP(E4,Desserts!A:D,4,FALSE)) * F4 -> 63 | N4: Row Labels | O4: Sum of Profit
A5: O0004 | B5: 2025-06-29 | C5: C097 | D5: R074 | E5: D042 | F5: 4 | G5: 188 | H5: =IF(VLOOKUP(C5,Customers!A:E,5,FALSE)>=1000,"YES","NO") -> NO | I5: =IF(H5="YES",G5*0.5,G5) -> 188 | J5: =(I5 - VLOOKUP(E5,Desserts!A:D,4,FALSE)) * F5 -> 396 | N5: R001 | O5: 1173
A6: O0005 | B6: 2025-04-07 | C6: C021 | D6: R023 | E6: D031 | F6: 4 | G6: 161 | H6: =IF(VLOOKUP(C6,Customers!A:E,5,FALSE)>=1000,"YES","NO") -> NO | I6: =IF(H6="YES",G6*0.5,G6) -> 161 | J6: =(I6 - VLOOKUP(E6,Desserts!A:D,4,FALSE)) * F6 -> 288 | N6: R002 | O6: 1555
A7: O0006 | B7: 2025-09-01 | C7: C062 | D7: R020 | E7: D034 | F7: 2 | G7: 158 | H7: =IF(VLOOKUP(C7,Customers!A:E,5,FALSE)>=1000,"YES","NO") -> YES | I7: =IF(H7="YES",G7*0.5,G7) -> 79 | J7: =(I7 - VLOOKUP(E7,Desserts!A:D,4,FALSE)) * F7 -> 14 | N7: R003 | O7: 760.5
A8: O0007 | B8: 2025-03-17 | C8: C074 | D8: R072 | E8: D009 | F8: 5 | G8: 160 | H8: =IF(VLOOKUP(C8,Customers!A:E,5,FALSE)>=1000,"YES","NO") -> NO | I8: =IF(H8="YES",G8*0.5,G8) -> 160 | J8: =(I8 - VLOOKUP(E8,Desserts!A:D,4,FALSE)) * F8 -> 380 | N8: R004 | O8: 1051
A9: O0008 | B9: 2025-02-11 | C9: C044 | D9: R095 | E9: D023 | F9: 4 | G9: 179 | H9: =IF(VLOOKUP(C9,Customers!A:E,5,FALSE)>=1000,"YES","NO") -> NO | I9: =IF(H9="YES",G9*0.5,G9) -> 179 | J9: =(I9 - VLOOKUP(E9,Desserts!A:D,4,FALSE)) * F9 -> 552 | N9: R005 | O9: 886
A10: O0009 | B10: 2025-03-07 | C10: C100 | D10: R054 | E10: D010 | F10: 4 | G10: 139 | H10: =IF(VLOOKUP(C10,Customers!A:E,5,FALSE)>=1000,"YES","NO") -> YES | I10: =IF(H10="YES",G10*0.5,G10) -> 69.5 | J10: =(I10 - VLOOKUP(E10,Desserts!A:D,4,FALSE)) * F10 -> 30 | N10: R006 | O10: 235
A11: O0010 | B11: 2025-10-21 | C11: C013 | D11: R049 | E11: D030 | F11: 5 | G11: 248 | H11: =IF(VLOOKUP(C11,Customers!A:E,5,FALSE)>=1000,"YES","NO") -> YES | I11: =IF(H11="YES",G11*0.5,G11) -> 124 | J11: =(I11 - VLOOKUP(E11,Desserts!A:D,4,FALSE)) * F11 -> 310 | N11: R007 | O11: 1966
A12: O0011 | B12: 2025-09-27 | C12: C051 | D12: R049 | E12: D049 | F12: 3 | G12: 178 | H12: =IF(VLOOKUP(C12,Customers!A:E,5,FALSE)>=1000,"YES","NO") -> YES | I12: =IF(H12="YES",G12*0.5,G12) -> 89 | J12: =(I12 - VLOOKUP(E12,Desserts!A:D,4,FALSE)) * F12 -> 144 | N12: R008 | O12: 952
A13: O0012 | B13: 2025-09-27 | C13: C034 | D13: R073 | E13: D004 | F13: 2 | G13: 240 | H13: =IF(VLOOKUP(C13,Customers!A:E,5,FALSE)>=1000,"YES","NO") -> NO | I13: =IF(H13="YES",G13*0.5,G13) -> 240 | J13: =(I13 - VLOOKUP(E13,Desserts!A:D,4,FALSE)) * F13 -> 394 | N13: R009 | O13: 17
A14: O0013 | B14: 2025-05-12 | C14: C092 | D14: R008 | E14: D047 | F14: 1 | G14: 121 | H14: =IF(VLOOKUP(C14,Customers!A:E,5,FALSE)>=1000,"YES","NO") -> NO | I14: =IF(H14="YES",G14*0.5,G14) -> 121 | J14: =(I14 - VLOOKUP(E14,Desserts!A:D,4,FALSE)) * F14 -> 36 | N14: R010 | O14: 284
A15: O0014 | B15: 2025-08-03 | C15: C001 | D15: R077 | E15: D029 | F15: 2 | G15: 233 | H15: =IF(VLOOKUP(C15,Customers!A:E,5,FALSE)>=1000,"YES","NO") -> NO | I15: =IF(H15="YES",G15*0.5,G15) -> 233 | J15: =(I15 - VLOOKUP(E15,Desserts!A:D,4,FALSE)) * F15 -> 326 | N15: R011 | O15: 941
A16: O0015 | B16: 2025-05-20 | C16: C063 | D16: R020 | E16: D047 | F16: 2 | G16: 228 | H16: =IF(VLOOKUP(C16,Customers!A:E,5,FALSE)>=1000,"YES","NO") -> NO | I16: =IF(H16="YES",G16*0.5,G16) -> 228 | J16: =(I16 - VLOOKUP(E16,Desserts!A:D,4,FALSE)) * F16 -> 286 | N16: R012 | O16: 554.5
... A104: O0103 | B104: 2025-12-22 | C104: C025 | D104: R054 | E104: D006 | F104: 5 | G104: 111 | H104: =IF(VLOOKUP(C104,Customers!A:E,5,FALSE)>=1000,"YES","NO") -> NO | I104: =IF(H104="YES",G104*0.5,G104) -> 111 | J104: =(I104 - VLOOKUP(E104,Desserts!A:D,4,FALSE)) * F104 -> 130 | N104: Grand Total | O104: 99689.5
A105: O0104 | B105: 2025-04-13 | C105: C020 | D105: R010 | E105: D035 | F105: 4 | G105: 124 | H105: =IF(VLOOKUP(C105,Customers!A:E,5,FALSE)>=1000,"YES","NO") -> YES | I105: =IF(H105="YES",G105*0.5,G105) -> 62 | J105: =(I105 - VLOOKUP(E105,Desserts!A:D,4,FALSE)) * F105 -> -36
A106: O0105 | B106: 2025-07-23 | C106: C025 | D106: R088 | E106: D005 | F106: 3 | G106: 181 | H106: =IF(VLOOKUP(C106,Customers!A:E,5,FALSE)>=1000,"YES","NO") -> NO | I106: =IF(H106="YES",G106*0.5,G106) -> 181 | J106: =(I106 - VLOOKUP(E106,Desserts!A:D,4,FALSE)) * F106 -> 339
A107: O0106 | B107: 2026-01-22 | C107: C055 | D107: R021 | E107: D027 | F107: 5 | G107: 182 | H107: =IF(VLOOKUP(C107,Customers!A:E,5,FALSE)>=1000,"YES","NO") -> NO | I107: =IF(H107="YES",G107*0.5,G107) -> 182 | J107: =(I107 - VLOOKUP(E107,Desserts!A:D,4,FALSE)) * F107 -> 660
A108: O0107 | B108: 2025-01-01 | C108: C062 | D108: R058 | E108: D030 | F108: 3 | G108: 124 | H108: =IF(VLOOKUP(C108,Customers!A:E,5,FALSE)>=1000,"YES","NO") -> YES | I108: =IF(H108="YES",G108*0.5,G108) -> 62 | J108: =(I108 - VLOOKUP(E108,Desserts!A:D,4,FALSE)) * F108 -> 0
A109: O0108 | B109: 2025-09-08 | C109: C071 | D109: R095 | E109: D025 | F109: 4 | G109: 177 | H109: =IF(VLOOKUP(C109,Customers!A:E,5,FALSE)>=1000,"YES","NO") -> YES | I109: =IF(H109="YES",G109*0.5,G109) -> 88.5 | J109: =(I109 - VLOOKUP(E109,Desserts!A:D,4,FALSE)) * F109 -> 46
A110: O0109 | B110: 2025-04-09 | C110: C041 | D110: R026 | E110: D047 | F110: 3 | G110: 112 | H110: =IF(VLOOKUP(C110,Customers!A:E,5,FALSE)>=1000,"YES","NO") -> NO | I110: =IF(H110="YES",G110*0.5,G110) -> 112 | J110: =(I110 - VLOOKUP(E110,Desserts!A:D,4,FALSE)) * F110 -> 81
A111: O0110 | B111: 2026-01-24 | C111: C014 | D111: R065 | E111: D022 | F111: 4 | G111: 233 | H111: =IF(VLOOKUP(C111,Customers!A:E,5,FALSE)>=1000,"YES","NO") -> YES | I111: =IF(H111="YES",G111*0.5,G111) -> 116.5 | J111: =(I111 - VLOOKUP(E111,Desserts!A:D,4,FALSE)) * F111 -> 206
A112: O0111 | B112: 2025-03-04 | C112: C003 | D112: R035 | E112: D009 | F112: 3 | G112: 182 | H112: =IF(VLOOKUP(C112,Customers!A:E,5,FALSE)>=1000,"YES","NO") -> NO | I112: =IF(H112="YES",G112*0.5,G112) -> 182 | J112: =(I112 - VLOOKUP(E112,Desserts!A:D,4,FALSE)) * F112 -> 294
A113: O0112 | B113: 2025-04-27 | C113: C095 | D113: R018 | E113: D029 | F113: 3 | G113: 171 | H113: =IF(VLOOKUP(C113,Customers!A:E,5,FALSE)>=1000,"YES","NO") -> YES | I113: =IF(H113="YES",G113*0.5,G113) -> 85.5 | J113: =(I113 - VLOOKUP(E113,Desserts!A:D,4,FALSE)) * F113 -> 46.5
A114: O0113 | B114: 2025-07-29 | C114: C099 | D114: R032 | E114: D030 | F114: 2 | G114: 154 | H114: =IF(VLOOKUP(C114,Customers!A:E,5,FALSE)>=1000,"YES","NO") -> YES | I114: =IF(H114="YES",G114*0.5,G114) -> 77 | J114: =(I114 - VLOOKUP(E114,Desserts!A:D,4,FALSE)) * F114 -> 30
A115: O0114 | B115: 2025-06-03 | C115: C061 | D115: R022 | E115: D024 | F115: 5 | G115: 228 | H115: =IF(VLOOKUP(C115,Customers!A:E,5,FALSE)>=1000,"YES","NO") -> NO | I115: =IF(H115="YES",G115*0.5,G115) -> 228 | J115: =(I115 - VLOOKUP(E115,Desserts!A:D,4,FALSE)) * F115 -> 860
A116: O0115 | B116: 2025-04-01 | C116: C050 | D116: R010 | E116: D027 | F116: 2 | G116: 131 | H116: =IF(VLOOKUP(C116,Customers!A:E,5,FALSE)>=1000,"YES","NO") -> YES | I116: =IF(H116="YES",G116*0.5,G116) -> 65.5 | J116: =(I116 - VLOOKUP(E116,Desserts!A:D,4,FALSE)) * F116 -> 31
... A501: O0500 | B501: 2025-11-10 | C501: C035 | D501: R096 | E501: D003 | F501: 2 | G501: 159 | H501: =IF(VLOOKUP(C501,Customers!A:E,5,FALSE)>=1000,"YES","NO") -> YES | I501: =IF(H501="YES",G501*0.5,G501) -> 79.5 | J501: =(I501 - VLOOKUP(E501,Desserts!A:D,4,FALSE)) * F501 -> -9

Sheet Discount_Eligible
A1: Order_ID | B1: Date | C1: Customer_ID | D1: Restaurant_ID | E1: Dessert_ID | F1: Quantity | G1: Price_Per_Item | H1: Discount_Eligible | I1: Discounted_Price | J1: Profit
A2: O0001 | B2: 2025-11-26 | C2: C016 | D2: R003 | E2: D044 | F2: 3 | G2: 173 | H2: =IF(VLOOKUP(C2,Customers!A:E,5,FALSE)>=1000,"YES","NO") -> YES | I2: =IF(H2="YES",G2*0.5,G2) -> 86.5 | J2: =(I2 - VLOOKUP(E2,Desserts!A:D,4,FALSE)) * F2 -> 49.5 | L2: Discount vs No Discount
A3: O0002 | B3: 2025-07-06 | C3: C069 | D3: R097 | E3: D001 | F3: 4 | G3: 135 | H3: =IF(VLOOKUP(C3,Customers!A:E,5,FALSE)>=1000,"YES","NO") -> YES | I3: =IF(H3="YES",G3*0.5,G3) -> 67.5 | J3: =(I3 - VLOOKUP(E3,Desserts!A:D,4,FALSE)) * F3 -> 14
A4: O0003 | B4: 2025-07-08 | C4: C079 | D4: R060 | E4: D015 | F4: 1 | G4: 142 | H4: =IF(VLOOKUP(C4,Customers!A:E,5,FALSE)>=1000,"YES","NO") -> NO | I4: =IF(H4="YES",G4*0.5,G4) -> 142 | J4: =(I4 - VLOOKUP(E4,Desserts!A:D,4,FALSE)) * F4 -> 63
A5: O0004 | B5: 2025-06-29 | C5: C097 | D5: R074 | E5: D042 | F5: 4 | G5: 188 | H5: =IF(VLOOKUP(C5,Customers!A:E,5,FALSE)>=1000,"YES","NO") -> NO | I5: =IF(H5="YES",G5*0.5,G5) -> 188 | J5: =(I5 - VLOOKUP(E5,Desserts!A:D,4,FALSE)) * F5 -> 396 | L5: Row Labels | M5: Sum of Profit
A6: O0005 | B6: 2025-04-07 | C6: C021 | D6: R023 | E6: D031 | F6: 4 | G6: 161 | H6: =IF(VLOOKUP(C6,Customers!A:E,5,FALSE)>=1000,"YES","NO") -> NO | I6: =IF(H6="YES",G6*0.5,G6) -> 161 | J6: =(I6 - VLOOKUP(E6,Desserts!A:D,4,FALSE)) * F6 -> 288 | L6: NO | M6: 83701
A7: O0006 | B7: 2025-09-01 | C7: C062 | D7: R020 | E7: D034 | F7: 2 | G7: 158 | H7: =IF(VLOOKUP(C7,Customers!A:E,5,FALSE)>=1000,"YES","NO") -> YES | I7: =IF(H7="YES",G7*0.5,G7) -> 79 | J7: =(I7 - VLOOKUP(E7,Desserts!A:D,4,FALSE)) * F7 -> 14 | L7: YES | M7: 15988.5
A8: O0007 | B8: 2025-03-17 | C8: C074 | D8: R072 | E8: D009 | F8: 5 | G8: 160 | H8: =IF(VLOOKUP(C8,Customers!A:E,5,FALSE)>=1000,"YES","NO") -> NO | I8: =IF(H8="YES",G8*0.5,G8) -> 160 | J8: =(I8 - VLOOKUP(E8,Desserts!A:D,4,FALSE)) * F8 -> 380 | L8: Grand Total | M8: 99689.5
A9: O0008 | B9: 2025-02-11 | C9: C044 | D9: R095 | E9: D023 | F9: 4 | G9: 179 | H9: =IF(VLOOKUP(C9,Customers!A:E,5,FALSE)>=1000,"YES","NO") -> NO | I9: =IF(H9="YES",G9*0.5,G9) -> 179 | J9: =(I9 - VLOOKUP(E9,Desserts!A:D,4,FALSE)) * F9 -> 552
A10: O0009 | B10: 2025-03-07 | C10: C100 | D10: R054 | E10: D010 | F10: 4 | G10: 139 | H10: =IF(VLOOKUP(C10,Customers!A:E,5,FALSE)>=1000,"YES","NO") -> YES | I10: =IF(H10="YES",G10*0.5,G10) -> 69.5 | J10: =(I10 - VLOOKUP(E10,Desserts!A:D,4,FALSE)) * F10 -> 30
A11: O0010 | B11: 2025-10-21 | C11: C013 | D11: R049 | E11: D030 | F11: 5 | G11: 248 | H11: =IF(VLOOKUP(C11,Customers!A:E,5,FALSE)>=1000,"YES","NO") -> YES | I11: =IF(H11="YES",G11*0.5,G11) -> 124 | J11: =(I11 - VLOOKUP(E11,Desserts!A:D,4,FALSE)) * F11 -> 310
A12: O0011 | B12: 2025-09-27 | C12: C051 | D12: R049 | E12: D049 | F12: 3 | G12: 178 | H12: =IF(VLOOKUP(C12,Customers!A:E,5,FALSE)>=1000,"YES","NO") -> YES | I12: =IF(H12="YES",G12*0.5,G12) -> 89 | J12: =(I12 - VLOOKUP(E12,Desserts!A:D,4,FALSE)) * F12 -> 144
A13: O0012 | B13: 2025-09-27 | C13: C034 | D13: R073 | E13: D004 | F13: 2 | G13: 240 | H13: =IF(VLOOKUP(C13,Customers!A:E,5,FALSE)>=1000,"YES","NO") -> NO | I13: =IF(H13="YES",G13*0.5,G13) -> 240 | J13: =(I13 - VLOOKUP(E13,Desserts!A:D,4,FALSE)) * F13 -> 394
A14: O0013 | B14: 2025-05-12 | C14: C092 | D14: R008 | E14: D047 | F14: 1 | G14: 121 | H14: =IF(VLOOKUP(C14,Customers!A:E,5,FALSE)>=1000,"YES","NO") -> NO | I14: =IF(H14="YES",G14*0.5,G14) -> 121 | J14: =(I14 - VLOOKUP(E14,Desserts!A:D,4,FALSE)) * F14 -> 36
A15: O0014 | B15: 2025-08-03 | C15: C001 | D15: R077 | E15: D029 | F15: 2 | G15: 233 | H15: =IF(VLOOKUP(C15,Customers!A:E,5,FALSE)>=1000,"YES","NO") -> NO | I15: =IF(H15="YES",G15*0.5,G15) -> 233 | J15: =(I15 - VLOOKUP(E15,Desserts!A:D,4,FALSE)) * F15 -> 326
A16: O0015 | B16: 2025-05-20 | C16: C063 | D16: R020 | E16: D047 | F16: 2 | G16: 228 | H16: =IF(VLOOKUP(C16,Customers!A:E,5,FALSE)>=1000,"YES","NO") -> NO | I16: =IF(H16="YES",G16*0.5,G16) -> 228 | J16: =(I16 - VLOOKUP(E16,Desserts!A:D,4,FALSE)) * F16 -> 286
A17: O0016 | B17: 2025-09-19 | C17: C061 | D17: R029 | E17: D039 | F17: 3 | G17: 202 | H17: =IF(VLOOKUP(C17,Customers!A:E,5,FALSE)>=1000,"YES","NO") -> NO | I17: =IF(H17="YES",G17*0.5,G17) -> 202 | J17: =(I17 - VLOOKUP(E17,Desserts!A:D,4,FALSE)) * F17 -> 471
A18: O0017 | B18: 2025-01-10 | C18: C094 | D18: R020 | E18: D018 | F18: 4 | G18: 132 | H18: =IF(VLOOKUP(C18,Customers!A:E,5,FALSE)>=1000,"YES","NO") -> NO | I18: =IF(H18="YES",G18*0.5,G18) -> 132 | J18: =(I18 - VLOOKUP(E18,Desserts!A:D,4,FALSE)) * F18 -> 228
A19: O0018 | B19: 2025-06-24 | C19: C079 | D19: R030 | E19: D042 | F19: 5 | G19: 226 | H19: =IF(VLOOKUP(C19,Customers!A:E,5,FALSE)>=1000,"YES","NO") -> NO | I19: =IF(H19="YES",G19*0.5,G19) -> 226 | J19: =(I19 - VLOOKUP(E19,Desserts!A:D,4,FALSE)) * F19 -> 685
A20: O0019 | B20: 2025-07-24 | C20: C017 | D20: R014 | E20: D031 | F20: 1 | G20: 225 | H20: =IF(VLOOKUP(C20,Customers!A:E,5,FALSE)>=1000,"YES","NO") -> NO | I20: =IF(H20="YES",G20*0.5,G20) -> 225 | J20: =(I20 - VLOOKUP(E20,Desserts!A:D,4,FALSE)) * F20 -> 136
... A501: O0500 | B501: 2025-11-10 | C501: C035 | D501: R096 | E501: D003 | F501: 2 | G501: 159 | H501: =IF(VLOOKUP(C501,Customers!A:E,5,FALSE)>=1000,"YES","NO") -> YES | I501: =IF(H501="YES",G501*0.5,G501) -> 79.5 | J501: =(I501 - VLOOKUP(E501,Desserts!A:D,4,FALSE)) * F501 -> -9

Sheet Monthly Profit
A1: Order_ID | B1: Date | C1: Real_Date | D1: Customer_ID | E1: Restaurant_ID | F1: Dessert_ID | G1: Quantity | H1: Price_Per_Item | I1: Discount_Eligible | J1: Discounted_Price | K1: Profit
A2: O0001 | B2: 45987 | C2: =--B2 -> 45987 | D2: C016 | E2: R003 | F2: D044 | G2: 3 | H2: 173 | I2: =IF(VLOOKUP(D2,Customers!A:E,5,FALSE)>=1000,"YES","NO") -> YES | J2: =IF(I2="YES",H2*0.5,H2) -> 86.5 | K2: =(J2 - VLOOKUP(F2,Desserts!A:D,4,FALSE)) * G2 -> 49.5 | N2: Monthly Profit
A3: O0002 | B3: 45844 | C3: =--B3 -> 45844 | D3: C069 | E3: R097 | F3: D001 | G3: 4 | H3: 135 | I3: =IF(VLOOKUP(D3,Customers!A:E,5,FALSE)>=1000,"YES","NO") -> YES | J3: =IF(I3="YES",H3*0.5,H3) -> 67.5 | K3: =(J3 - VLOOKUP(F3,Desserts!A:D,4,FALSE)) * G3 -> 14
A4: O0003 | B4: 45846 | C4: =--B4 -> 45846 | D4: C079 | E4: R060 | F4: D015 | G4: 1 | H4: 142 | I4: =IF(VLOOKUP(D4,Customers!A:E,5,FALSE)>=1000,"YES","NO") -> NO | J4: =IF(I4="YES",H4*0.5,H4) -> 142 | K4: =(J4 - VLOOKUP(F4,Desserts!A:D,4,FALSE)) * G4 -> 63 | N4: Row Labels | O4: Sum of Profit
A5: O0004 | B5: 45837 | C5: =--B5 -> 45837 | D5: C097 | E5: R074 | F5: D042 | G5: 4 | H5: 188 | I5: =IF(VLOOKUP(D5,Customers!A:E,5,FALSE)>=1000,"YES","NO") -> NO | J5: =IF(I5="YES",H5*0.5,H5) -> 188 | K5: =(J5 - VLOOKUP(F5,Desserts!A:D,4,FALSE)) * G5 -> 396 | N5: 2025 | O5: 90430
A6: O0005 | B6: 45754 | C6: =--B6 -> 45754 | D6: C021 | E6: R023 | F6: D031 | G6: 4 | H6: 161 | I6: =IF(VLOOKUP(D6,Customers!A:E,5,FALSE)>=1000,"YES","NO") -> NO | J6: =IF(I6="YES",H6*0.5,H6) -> 161 | K6: =(J6 - VLOOKUP(F6,Desserts!A:D,4,FALSE)) * G6 -> 288 | N6: Qtr1 | O6: 18962
A7: O0006 | B7: 45901 | C7: =--B7 -> 45901 | D7: C062 | E7: R020 | F7: D034 | G7: 2 | H7: 158 | I7: =IF(VLOOKUP(D7,Customers!A:E,5,FALSE)>=1000,"YES","NO") -> YES | J7: =IF(I7="YES",H7*0.5,H7) -> 79 | K7: =(J7 - VLOOKUP(F7,Desserts!A:D,4,FALSE)) * G7 -> 14 | N7: Jan | O7: 4993
A8: O0007 | B8: 45733 | C8: =--B8 -> 45733 | D8: C074 | E8: R072 | F8: D009 | G8: 5 | H8: 160 | I8: =IF(VLOOKUP(D8,Customers!A:E,5,FALSE)>=1000,"YES","NO") -> NO | J8: =IF(I8="YES",H8*0.5,H8) -> 160 | K8: =(J8 - VLOOKUP(F8,Desserts!A:D,4,FALSE)) * G8 -> 380 | N8: 45658 | O8: 0
A9: O0008 | B9: 45699 | C9: =--B9 -> 45699 | D9: C044 | E9: R095 | F9: D023 | G9: 4 | H9: 179 | I9: =IF(VLOOKUP(D9,Customers!A:E,5,FALSE)>=1000,"YES","NO") -> NO | J9: =IF(I9="YES",H9*0.5,H9) -> 179 | K9: =(J9 - VLOOKUP(F9,Desserts!A:D,4,FALSE)) * G9 -> 552 | N9: 45659 | O9: 39
A10: O0009 | B10: 45723 | C10: =--B10 -> 45723 | D10: C100 | E10: R054 | F10: D010 | G10: 4 | H10: 139 | I10: =IF(VLOOKUP(D10,Customers!A:E,5,FALSE)>=1000,"YES","NO") -> YES | J10: =IF(I10="YES",H10*0.5,H10) -> 69.5 | K10: =(J10 - VLOOKUP(F10,Desserts!A:D,4,FALSE)) * G10 -> 30 | N10: 45660 | O10: -11
A11: O0010 | B11: 45951 | C11: =--B11 -> 45951 | D11: C013 | E11: R049 | F11: D030 | G11: 5 | H11: 248 | I11: =IF(VLOOKUP(D11,Customers!A:E,5,FALSE)>=1000,"YES","NO") -> YES | J11: =IF(I11="YES",H11*0.5,H11) -> 124 | K11: =(J11 - VLOOKUP(F11,Desserts!A:D,4,FALSE)) * G11 -> 310 | N11: 45661 | O11: 762
A12: O0011 | B12: 45927 | C12: =--B12 -> 45927 | D12: C051 | E12: R049 | F12: D049 | G12: 3 | H12: 178 | I12: =IF(VLOOKUP(D12,Customers!A:E,5,FALSE)>=1000,"YES","NO") -> YES | J12: =IF(I12="YES",H12*0.5,H12) -> 89 | K12: =(J12 - VLOOKUP(F12,Desserts!A:D,4,FALSE)) * G12 -> 144 | N12: 45665 | O12: 626
A13: O0012 | B13: 45927 | C13: =--B13 -> 45927 | D13: C034 | E13: R073 | F13: D004 | G13: 2 | H13: 240 | I13: =IF(VLOOKUP(D13,Customers!A:E,5,FALSE)>=1000,"YES","NO") -> NO | J13: =IF(I13="YES",H13*0.5,H13) -> 240 | K13: =(J13 - VLOOKUP(F13,Desserts!A:D,4,FALSE)) * G13 -> 394 | N13: 45666 | O13: 472
A14: O0013 | B14: 45789 | C14: =--B14 -> 45789 | D14: C092 | E14: R008 | F14: D047 | G14: 1 | H14: 121 | I14: =IF(VLOOKUP(D14,Customers!A:E,5,FALSE)>=1000,"YES","NO") -> NO | J14: =IF(I14="YES",H14*0.5,H14) -> 121 | K14: =(J14 - VLOOKUP(F14,Desserts!A:D,4,FALSE)) * G14 -> 36 | N14: 45667 | O14: 228
A15: O0014 | B15: 45872 | C15: =--B15 -> 45872 | D15: C001 | E15: R077 | F15: D029 | G15: 2 | H15: 233 | I15: =IF(VLOOKUP(D15,Customers!A:E,5,FALSE)>=1000,"YES","NO") -> NO | J15: =IF(I15="YES",H15*0.5,H15) -> 233 | K15: =(J15 - VLOOKUP(F15,Desserts!A:D,4,FALSE)) * G15 -> 326 | N15: 45668 | O15: 185
A16: O0015 | B16: 45797 | C16: =--B16 -> 45797 | D16: C063 | E16: R020 | F16: D047 | G16: 2 | H16: 228 | I16: =IF(VLOOKUP(D16,Customers!A:E,5,FALSE)>=1000,"YES","NO") -> NO | J16: =IF(I16="YES",H16*0.5,H16) -> 228 | K16: =(J16 - VLOOKUP(F16,Desserts!A:D,4,FALSE)) * G16 -> 286 | N16: 45670 | O16: 784
A17: O0016 | B17: 45919 | C17: =--B17 -> 45919 | D17: C061 | E17: R029 | F17: D039 | G17: 3 | H17: 202 | I17: =IF(VLOOKUP(D17,Customers!A:E,5,FALSE)>=1000,"YES","NO") -> NO | J17: =IF(I17="YES",H17*0.5,H17) -> 202 | K17: =(J17 - VLOOKUP(F17,Desserts!A:D,4,FALSE)) * G17 -> 471 | N17: 45671 | O17: 82
A18: O0017 | B18: 45667 | C18: =--B18 -> 45667 | D18: C094 | E18: R020 | F18: D018 | G18: 4 | H18: 132 | I18: =IF(VLOOKUP(D18,Customers!A:E,5,FALSE)>=1000,"YES","NO") -> NO | J18: =IF(I18="YES",H18*0.5,H18) -> 132 | K18: =(J18 - VLOOKUP(F18,Desserts!A:D,4,FALSE)) * G18 -> 228 | N18: 45673 | O18: 79
A19: O0018 | B19: 45832 | C19: =--B19 -> 45832 | D19: C079 | E19: R030 | F19: D042 | G19: 5 | H19: 226 | I19: =IF(VLOOKUP(D19,Customers!A:E,5,FALSE)>=1000,"YES","NO") -> NO | J19: =IF(I19="YES",H19*0.5,H19) -> 226 | K19: =(J19 - VLOOKUP(F19,Desserts!A:D,4,FALSE)) * G19 -> 685 | N19: 45674 | O19: 568
... A26: O0025 | B26: 45984 | C26: =--B26 -> 45984 | D26: C076 | E26: R005 | F26: D027 | G26: 2 | H26: 104 | I26: =IF(VLOOKUP(D26,Customers!A:E,5,FALSE)>=1000,"YES","NO") -> YES | J26: =IF(I26="YES",H26*0.5,H26) -> 52 | K26: =(J26 - VLOOKUP(F26,Desserts!A:D,4,FALSE)) * G26 -> 4 | N26: 45686 | O26: 345
A27: O0026 | B27: 45966 | C27: =--B27 -> 45966 | D27: C016 | E27: R075 | F27: D015 | G27: 5 | H27: 206 | I27: =IF(VLOOKUP(D27,Customers!A:E,5,FALSE)>=1000,"YES","NO") -> YES | J27: =IF(I27="YES",H27*0.5,H27) -> 103 | K27: =(J27 - VLOOKUP(F27,Desserts!A:D,4,FALSE)) * G27 -> 120 | N27: Feb | O27: 6458.5
A28: O0027 | B28: 45788 | C28: =--B28 -> 45788 | D28: C083 | E28: R098 | F28: D016 | G28: 5 | H28: 176 | I28: =IF(VLOOKUP(D28,Customers!A:E,5,FALSE)>=1000,"YES","NO") -> YES | J28: =IF(I28="YES",H28*0.5,H28) -> 88 | K28: =(J28 - VLOOKUP(F28,Desserts!A:D,4,FALSE)) * G28 -> 95 | N28: Mar | O28: 7510.5
A29: O0028 | B29: 45666 | C29: =--B29 -> 45666 | D29: C066 | E29: R042 | F29: D036 | G29: 2 | H29: 201 | I29: =IF(VLOOKUP(D29,Customers!A:E,5,FALSE)>=1000,"YES","NO") -> YES | J29: =IF(I29="YES",H29*0.5,H29) -> 100.5 | K29: =(J29 - VLOOKUP(F29,Desserts!A:D,4,FALSE)) * G29 -> 77 | N29: Qtr2 | O29: 26059.5
A30: O0029 | B30: 45675 | C30: =--B30 -> 45675 | D30: C031 | E30: R032 | F30: D049 | G30: 1 | H30: 222 | I30: =IF(VLOOKUP(D30,Customers!A:E,5,FALSE)>=1000,"YES","NO") -> NO | J30: =IF(I30="YES",H30*0.5,H30) -> 222 | K30: =(J30 - VLOOKUP(F30,Desserts!A:D,4,FALSE)) * G30 -> 181 | N30: Qtr3 | O30: 22452
A31: O0030 | B31: 45727 | C31: =--B31 -> 45727 | D31: C023 | E31: R032 | F31: D001 | G31: 4 | H31: 156 | I31: =IF(VLOOKUP(D31,Customers!A:E,5,FALSE)>=1000,"YES","NO") -> NO | J31: =IF(I31="YES",H31*0.5,H31) -> 156 | K31: =(J31 - VLOOKUP(F31,Desserts!A:D,4,FALSE)) * G31 -> 368 | N31: Qtr4 | O31: 22956.5
A32: O0031 | B32: 45880 | C32: =--B32 -> 45880 | D32: C030 | E32: R076 | F32: D007 | G32: 5 | H32: 175 | I32: =IF(VLOOKUP(D32,Customers!A:E,5,FALSE)>=1000,"YES","NO") -> NO | J32: =IF(I32="YES",H32*0.5,H32) -> 175 | K32: =(J32 - VLOOKUP(F32,Desserts!A:D,4,FALSE)) * G32 -> 540 | N32: 2026 | O32: 9259.5
A33: O0032 | B33: 45822 | C33: =--B33 -> 45822 | D33: C051 | E33: R053 | F33: D017 | G33: 2 | H33: 154 | I33: =IF(VLOOKUP(D33,Customers!A:E,5,FALSE)>=1000,"YES","NO") -> YES | J33: =IF(I33="YES",H33*0.5,H33) -> 77 | K33: =(J33 - VLOOKUP(F33,Desserts!A:D,4,FALSE)) * G33 -> 34 | N33: Qtr1 | O33: 9259.5
A34: O0033 | B34: 46053 | C34: =--B34 -> 46053 | D34: C016 | E34: R028 | F34: D015 | G34: 2 | H34: 183 | I34: =IF(VLOOKUP(D34,Customers!A:E,5,FALSE)>=1000,"YES","NO") -> YES | J34: =IF(I34="YES",H34*0.5,H34) -> 91.5 | K34: =(J34 - VLOOKUP(F34,Desserts!A:D,4,FALSE)) * G34 -> 25 | N34: Jan | O34: 7974.5
A35: O0034 | B35: 45901 | C35: =--B35 -> 45901 | D35: C005 | E35: R093 | F35: D007 | G35: 3 | H35: 222 | I35: =IF(VLOOKUP(D35,Customers!A:E,5,FALSE)>=1000,"YES","NO") -> NO | J35: =IF(I35="YES",H35*0.5,H35) -> 222 | K35: =(J35 - VLOOKUP(F35,Desserts!A:D,4,FALSE)) * G35 -> 465 | N35: 46023 | O35: 96
A36: O0035 | B36: 46021 | C36: =--B36 -> 46021 | D36: C059 | E36: R085 | F36: D003 | G36: 1 | H36: 217 | I36: =IF(VLOOKUP(D36,Customers!A:E,5,FALSE)>=1000,"YES","NO") -> YES | J36: =IF(I36="YES",H36*0.5,H36) -> 108.5 | K36: =(J36 - VLOOKUP(F36,Desserts!A:D,4,FALSE)) * G36 -> 24.5 | N36: 46024 | O36: 865
A37: O0036 | B37: 45699 | C37: =--B37 -> 45699 | D37: C064 | E37: R076 | F37: D029 | G37: 5 | H37: 126 | I37: =IF(VLOOKUP(D37,Customers!A:E,5,FALSE)>=1000,"YES","NO") -> YES | J37: =IF(I37="YES",H37*0.5,H37) -> 63 | K37: =(J37 - VLOOKUP(F37,Desserts!A:D,4,FALSE)) * G37 -> -35 | N37: 46025 | O37: -11.5
A38: O0037 | B38: 45819 | C38: =--B38 -> 45819 | D38: C031 | E38: R052 | F38: D042 | G38: 5 | H38: 139 | I38: =IF(VLOOKUP(D38,Customers!A:E,5,FALSE)>=1000,"YES","NO") -> NO | J38: =IF(I38="YES",H38*0.5,H38) -> 139 | K38: =(J38 - VLOOKUP(F38,Desserts!A:D,4,FALSE)) * G38 -> 250 | N38: 46028 | O38: 60
A39: O0038 | B39: 45763 | C39: =--B39 -> 45763 | D39: C023 | E39: R046 | F39: D030 | G39: 1 | H39: 203 | I39: =IF(VLOOKUP(D39,Customers!A:E,5,FALSE)>=1000,"YES","NO") -> NO | J39: =IF(I39="YES",H39*0.5,H39) -> 203 | K39: =(J39 - VLOOKUP(F39,Desserts!A:D,4,FALSE)) * G39 -> 141 | N39: 46029 | O39: 1040
A40: O0039 | B40: 45748 | C40: =--B40 -> 45748 | D40: C035 | E40: R033 | F40: D004 | G40: 2 | H40: 174 | I40: =IF(VLOOKUP(D40,Customers!A:E,5,FALSE)>=1000,"YES","NO") -> YES | J40: =IF(I40="YES",H40*0.5,H40) -> 87 | K40: =(J40 - VLOOKUP(F40,Desserts!A:D,4,FALSE)) * G40 -> 88 | N40: 46031 | O40: 606
A41: O0040 | B41: 46014 | C41: =--B41 -> 46014 | D41: C033 | E41: R034 | F41: D032 | G41: 1 | H41: 219 | I41: =IF(VLOOKUP(D41,Customers!A:E,5,FALSE)>=1000,"YES","NO") -> NO | J41: =IF(I41="YES",H41*0.5,H41) -> 219 | K41: =(J41 - VLOOKUP(F41,Desserts!A:D,4,FALSE)) * G41 -> 136 | N41: 46033 | O41: 338
A42: O0041 | B42: 45782 | C42: =--B42 -> 45782 | D42: C034 | E42: R090 | F42: D032 | G42: 3 | H42: 243 | I42: =IF(VLOOKUP(D42,Customers!A:E,5,FALSE)>=1000,"YES","NO") -> NO | J42: =IF(I42="YES",H42*0.5,H42) -> 243 | K42: =(J42 - VLOOKUP(F42,Desserts!A:D,4,FALSE)) * G42 -> 480 | N42: 46035 | O42: 279
A43: O0042 | B43: 45894 | C43: =--B43 -> 45894 | D43: C026 | E43: R090 | F43: D002 | G43: 3 | H43: 234 | I43: =IF(VLOOKUP(D43,Customers!A:E,5,FALSE)>=1000,"YES","NO") -> NO | J43: =IF(I43="YES",H43*0.5,H43) -> 234 | K43: =(J43 - VLOOKUP(F43,Desserts!A:D,4,FALSE)) * G43 -> 498 | N43: 46037 | O43: 65.5
A44: O0043 | B44: 45723 | C44: =--B44 -> 45723 | D44: C030 | E44: R047 | F44: D024 | G44: 5 | H44: 115 | I44: =IF(VLOOKUP(D44,Customers!A:E,5,FALSE)>=1000,"YES","NO") -> NO | J44: =IF(I44="YES",H44*0.5,H44) -> 115 | K44: =(J44 - VLOOKUP(F44,Desserts!A:D,4,FALSE)) * G44 -> 295 | N44: 46038 | O44: 315
A45: O0044 | B45: 45715 | C45: =--B45 -> 45715 | D45: C071 | E45: R075 | F45: D022 | G45: 1 | H45: 124 | I45: =IF(VLOOKUP(D45,Customers!A:E,5,FALSE)>=1000,"YES","NO") -> YES | J45: =IF(I45="YES",H45*0.5,H45) -> 62 | K45: =(J45 - VLOOKUP(F45,Desserts!A:D,4,FALSE)) * G45 -> -3 | N45: 46039 | O45: -38
A46: O0045 | B46: 45694 | C46: =--B46 -> 45694 | D46: C062 | E46: R025 | F46: D029 | G46: 5 | H46: 211 | I46: =IF(VLOOKUP(D46,Customers!A:E,5,FALSE)>=1000,"YES","NO") -> YES | J46: =IF(I46="YES",H46*0.5,H46) -> 105.5 | K46: =(J46 - VLOOKUP(F46,Desserts!A:D,4,FALSE)) * G46 -> 177.5 | N46: 46041 | O46: -12
...
